2018-03-20 03:18:48,772 - functest.utils.functest_utils - DEBUG - Executing command: 'prepare_env start'
2018-03-20 03:18:49,454 - functest.ci.prepare_env - INFO - ######### Preparing Functest environment #########

2018-03-20 03:18:49,455 - functest.ci.prepare_env - INFO - ==============================================
2018-03-20 03:18:49,456 - functest.ci.prepare_env - INFO - Verifying OpenStack deployment...
2018-03-20 03:18:54,473 - functest.ci.check_deployment - ERROR - xxx.xxx.xxx.xxx:5000 is not reachable.
Traceback (most recent call last):
  File "/usr/lib/python2.7/site-packages/functest/ci/check_deployment.py", line 45, in verify_connectivity
    connection.connect((ip, port))
  File "/usr/lib/python2.7/socket.py", line 228, in meth
    return getattr(self._sock,name)(*args)
gaierror: [Errno -3] Try again
2018-03-20 03:18:54,474 - functest.ci.prepare_env - ERROR - OS_AUTH_URL http://xxx.xxx.xxx.xxx:5000/v3 is not reachable.
2018-03-20 03:18:54,516 - functest.utils.functest_utils - ERROR - The command 'prepare_env start' failed.
